<?xml version="1.0"?>
<robot name="robot" xmlns:xacro="http://www.ros.org/wiki/xacro">

  <xacro:include filename="common_properties.xacro" />
  <xacro:include filename="lidar.xacro" />
  <xacro:include filename="mobile_base_gazebo.xacro" />


   <material name="white">
     <color rgba="1 1 1 1"/>
   </material>
   <material name="green">
     <color rgba="0 1 0 1"/>
   </material>
   <material name="gray">
     <color rgba="0.5 0.5 0.5 1"/>
   </material>

   <link name="base_footprint"/>

   <link name="base_link">
      <visual>
        <geometry>
          <cylinder radius="0.1" length="0.124"/>
        </geometry>
        <origin xyz="0 0 0" rpy="0 0 0"/>
        <material name="white"/>
      </visual>
      <collision>
        <geometry>
          <cylinder radius="0.1" length="0.124"/>
        </geometry>
        <origin xyz="0 0 0" rpy="0 0 0"/>
      </collision>
      <xacro:cylinder_inertia m="1" r="0.1" l="0.124" o_xyz="0 0 0" o_rpy="0 0 0" />
   </link>

   <joint name="base_joint" type="fixed">
       <parent link="base_footprint"/>
       <child link="base_link"/>
       <origin xyz="0 0 0.079" rpy="0 0 0"/>
   </joint>

   <link name="raspberry_link">
      <visual>
        <geometry>
          <box size="0.055 0.085 0.035"/>
        </geometry>
        <origin xyz="0 0 0" rpy="0 0 0"/>
        <material name="green"/>
      </visual>
      <collision>
        <geometry>
          <box size="0.055 0.085 0.035"/>
        </geometry>
        <origin xyz="0 0 0" rpy="0 0 0"/>
      </collision>
      <xacro:box_inertia m="0.3" x="0.055" y="0.085" z="0.035" o_xyz="0 0 0" o_rpy="0 0 0" />
   </link>

   <joint name="base_raspberry_joint" type="fixed">
      <parent link="base_link"/>
      <child link="raspberry_link"/>
      <origin xyz="-0.06 0 0.0795" rpy="0 0 0"/>
   </joint>

   <link name="right_wheel_link">
      <visual>
         <geometry>
           <cylinder radius="0.033" length="0.03"/>
         </geometry>
         <origin xyz="0 0 0" rpy="1.57 0 0"/>
         <material name="gray"/>
      </visual>
      <collision>
         <geometry>
           <cylinder radius="0.033" length="0.03"/>
         </geometry>
         <origin xyz="0 0 0" rpy="1.57 0 0"/>
      </collision>
      <xacro:cylinder_inertia m="0.1" r="0.033" l="0.03" o_xyz="0 0 0" o_rpy="1.57 0 0" />
   </link>

   <joint name="base_right_wheel_joint" type="continuous">
      <parent link="base_link"/>
      <child link="right_wheel_link"/>
      <origin xyz="0 -0.115 -0.045" rpy="0 0 0"/>
      <axis xyz="0 1 0"/>
   </joint>

   <link name="left_wheel_link">
      <visual>
         <geometry>
           <cylinder radius="0.033" length="0.03"/>
         </geometry>
         <origin xyz="0 0 0" rpy="1.57 0 0"/>
         <material name="gray"/>
      </visual>
      <collision>
         <geometry>
           <cylinder radius="0.033" length="0.03"/>
         </geometry>
         <origin xyz="0 0 0" rpy="1.57 0 0"/>
      </collision>
      <xacro:cylinder_inertia m="0.1" r="0.033" l="0.03" o_xyz="0 0 0" o_rpy="1.57 0 0" />
   </link>

   <joint name="base_left_wheel_joint" type="continuous">
      <parent link="base_link"/>
      <child link="left_wheel_link"/>
      <origin xyz="0 0.115 -0.045" rpy="0 0 0"/>
      <axis xyz="0 1 0"/>
   </joint>

   <link name="caster_wheel_link">
      <visual>
         <geometry>
           <sphere radius="0.017"/>
         </geometry>
         <origin xyz="0 0 0" rpy="0 0 0"/>
         <material name="gray"/>
      </visual>
      <collision>
         <geometry>
           <sphere radius="0.017"/>
         </geometry>
         <origin xyz="0 0 0" rpy="0 0 0"/>
      </collision>
      <xacro:sphere_inertia m="0.2" r="0.017" o_xyz="0 0 0" o_rpy="0 0 0" />
   </link>

   <joint name="base_caster_wheel_joint" type="fixed">
       <parent link="base_link"/>
       <child link="caster_wheel_link"/>
       <origin xyz="0.085 0 -0.062" rpy="0 0 0"/>
   </joint>

</robot>